<!-- Robot limits pulled from https://frankaemika.github.io/docs/control_parameters.html#constants -->
<!-- Modified from the original source code at
        1) https://github.com/vikashplus/franka
    which was originally written by Vikash Kumar and licensed under the Apache License= -->
<mujocoinclude>
	<body name="panda0_link0" childclass="panda" >
        <camera name="cam_root" mode="trackcom" pos="0 3 0" xyaxes="-1 0 0 0 0 1"/>
        <geom class="panda_viz" mesh="link0_viz"/>
        <geom class="panda_col" mesh="link0_col" mass="2.91242"/>
        <site name="panda0_link0_s0" pos="0 0 0" size="0.01 0.01"/>
        <site name="panda0_link0_s1" pos="0 0 0.14" size="0.01 0.01"/>

        <body name="panda0_link1" pos="0 0 0.333">
            <!--joint is designed in such a way that it always align with body's z axis-->
            <!--thus it's also a good choice to let the site have the same orientation as the body-->
            <joint name="panda0_joint1" range="-2.8973 2.8973" class="panda_arm"/>
            <geom class="panda_viz" mesh="link1_viz"/>
            <geom class="panda_col" mesh="link1_col" mass="2.7063"/>
            <site name="panda0_link1_s0" pos="0 0 -0.193" size="0.01 0.01"/>
            <site name="panda0_link1_s1" pos="0 0 0" size="0.01 0.01"/>

            <body name="panda0_link2" pos="0 0 0" quat="0.707107 -0.707107 0 0">
                <joint name="panda0_joint2" range="-1.7628 1.7628" class="panda_arm"/>
                <geom class="panda_viz" mesh="link2_viz"/>
                <geom class="panda_col" mesh="link2_col" mass="2.73046"/>
                <site name="panda0_link2_s0" pos="0 0 0" size="0.01 0.01"/>
                <site name="panda0_link2_s1" pos="0 -0.194 0" size="0.01 0.01"/>

                <body name="panda0_link3" pos="0 -0.316 0" quat="0.707107 0.707107 0 0">
                    <joint name="panda0_joint3" range="-2.8973 2.8973" class="panda_arm"/>
                    <geom class="panda_viz" mesh="link3_viz"/>
                    <geom class="panda_col" mesh="link3_col" mass="2.04104"/>
                    <site name="panda0_link3_s0" pos="0 0 -0.122" size="0.01 0.01"/>
                    <site name="panda0_link3_s1" pos="0.0825 0 0" size="0.01 0.01"/>

                    <body name="panda0_link4" pos="0.0825 0 0" quat="0.707107 0.707107 0 0">
                        <joint name="panda0_joint4" range="-3.0718 -0.4" class="panda_arm"/>
                        <geom class="panda_viz" mesh="link4_viz"/>
                        <geom class="panda_col" mesh="link4_col" mass="2.08129"/>
                        <site name="panda0_link4_s0" pos="0 0 0" size="0.01 0.01"/>
                        <site name="panda0_link4_s1" pos="-0.0825 0.125 0" size="0.01 0.01"/>

                        <body name="panda0_link5" pos="-0.0825 0.384 0" quat="0.707107 -0.707107 0 0">
                            <joint name="panda0_joint5" range="-2.8973 2.8973" class="panda_forearm"/>
                            <geom class="panda_viz" mesh="link5_viz"/>
                            <geom class="panda_col" mesh="link5_col" mass="3.00049"/>
                            <site name="panda0_link5_s0" pos="0 0 -0.259" size="0.01 0.01"/>
                            <site name="panda0_link5_s1" pos="0 0 0" size="0.01 0.01"/>

                            <body name="panda0_link6" pos="0 0 0" euler='1.57 0 1.57'>
                                <joint name="panda0_joint6" range="-1.6573 2.1127" class="panda_forearm"/>
                                <!-- <body name="panda0_link6" pos="0 0 0" quat="0.707107 0.707107 0 0"> -->
                                <!-- <joint name="panda0_joint6" range="-0.0873 3.8223" class="panda_forearm"/> -->
                                <geom class="panda_viz" mesh="link6_viz"/>
                                <geom class="panda_col" mesh="link6_col" mass="1.3235"/>
                                <site name="panda0_link6_s0" pos="0 0 0" size="0.01 0.01"/>
                                <site name="panda0_link6_s1" pos="0.088 -0.05 0" size="0.01 0.01"/>

                                <body name="panda0_link7" pos="0.088 0 0" euler='1.57 0 0'>
                                    <joint name="panda0_joint7" range="-2.8973 2.8973" class="panda_forearm"/>
                                    <!-- <body name="panda0_link7" pos="0.088 0 0" quat="0.707107 0.707107 0 0"> -->
                                    <!-- <joint name="panda0_joint7" range="-2.9671 2.9671" class="panda_forearm"/> -->
                                    <geom class="panda_viz" mesh="link7_viz"/>
                                    <geom class="panda_col" mesh="link7_col" mass="0.2"/>
                                    <geom pos="0 0 0.107" quat="1 0 0 0" class="panda_viz" mesh="hand_viz"/>
                                    <geom pos="0 0 0.107" quat="1 0 0 0" class="panda_col" mesh="hand_col" mass="0.81909"/>

                                    <site name="panda0_link7_s0" pos="0 0 0.05" size="0.01 0.01"/>
                                    <site name="panda0_link7_s1" pos="0 0 0.21" size="0.01 0.01"/>

                                    <site name='end_effector0' pos='0 0 .210' size='0.01' euler='0 0 0'/>
                                    <site name='tip0' pos='0 0 .210' size='0.01' euler='0 0 0'/>

                                </body>
                            </body>
                        </body>
                    </body>
                </body>
            </body>
        </body>
    </body>
</mujocoinclude>
