<mujocoinclude>
<!--    <compiler angle="radian" balanceinertia="true"/>-->
    <asset>
        <mesh class="Armar4" name="ArmL_Elb1_joint" file="ArmL_Elb1_joint_visu.stl"/>
        <mesh class="Armar4" name="ArmL_Elb2_joint" file="ArmL_Elb2_joint_visu.stl"/>
        <mesh class="Armar4" name="ArmL_Sho1_joint" file="ArmL_Sho1_joint_visu.stl"/>
        <mesh class="Armar4" name="ArmL_Sho2_joint" file="ArmL_Sho2_joint_visu.stl"/>
        <mesh class="Armar4" name="ArmL_Sho3_joint" file="ArmL_Sho3_joint_visu.stl"/>
        <mesh class="Armar4" name="ArmL_Sho4_joint" file="ArmL_Sho4_joint_visu.stl"/>
        <mesh class="Armar4" name="ArmL_Wri1_joint" file="ArmL_Wri1_joint_visu.stl"/>
        <mesh class="Armar4" name="ArmL_Wri2_joint" file="ArmL_Wri2_joint_visu.stl"/>
        <mesh class="Armar4" name="ArmR_Elb1_joint" file="ArmR_Elb1_joint_visu.stl"/>
        <mesh class="Armar4" name="ArmR_Elb2_joint" file="ArmR_Elb2_joint_visu.stl"/>
        <mesh class="Armar4" name="ArmR_Sho1_joint" file="ArmR_Sho1_joint_visu.stl"/>
        <mesh class="Armar4" name="ArmR_Sho2_joint" file="ArmR_Sho2_joint_visu.stl"/>
        <mesh class="Armar4" name="ArmR_Sho3_joint" file="ArmR_Sho3_joint_visu.stl"/>
        <mesh class="Armar4" name="ArmR_Sho4_joint" file="ArmR_Sho4_joint_visu.stl"/>
        <mesh class="Armar4" name="ArmR_Wri1_joint" file="ArmR_Wri1_joint_visu.stl"/>
        <mesh class="Armar4" name="ArmR_Wri2_joint" file="ArmR_Wri2_joint_visu.stl"/>
        <mesh class="Armar4" name="EyeL_1_joint" file="EyeL_1_joint_visu.stl"/>
        <mesh class="Armar4" name="EyeL_2_joint" file="EyeL_2_joint_visu.stl"/>
        <mesh class="Armar4" name="EyeR_1_joint" file="EyeR_1_joint_visu.stl"/>
        <mesh class="Armar4" name="EyeR_2_joint" file="EyeR_2_joint_visu.stl"/>
        <mesh class="Armar4" name="HandL_Finger_Index1_joint" file="HandL_Finger_Index1_joint_visu.stl"/>
        <mesh class="Armar4" name="HandL_Finger_Index2_joint" file="HandL_Finger_Index2_joint_visu.stl"/>
        <mesh class="Armar4" name="HandL_Finger_Middle1_joint" file="HandL_Finger_Middle1_joint_visu.stl"/>
        <mesh class="Armar4" name="HandL_Finger_Middle2_joint" file="HandL_Finger_Middle2_joint_visu.stl"/>
        <mesh class="Armar4" name="HandL_Finger_Pinky1_joint" file="HandL_Finger_Pinky1_joint_visu.stl"/>
        <mesh class="Armar4" name="HandL_Finger_Pinky2_joint" file="HandL_Finger_Pinky2_joint_visu.stl"/>
        <mesh class="Armar4" name="HandL_Finger_Ring1_joint" file="HandL_Finger_Ring1_joint_visu.stl"/>
        <mesh class="Armar4" name="HandL_Finger_Ring2_joint" file="HandL_Finger_Ring2_joint_visu.stl"/>
        <mesh class="Armar4" name="HandL_Finger_Thumb1_joint" file="HandL_Finger_Thumb1_joint_visu.stl"/>
        <mesh class="Armar4" name="HandL_Finger_Thumb2_joint" file="HandL_Finger_Thumb2_joint_visu.stl"/>
        <mesh class="Armar4" name="HandL_Finger_Thumb3_joint" file="HandL_Finger_Thumb3_joint_visu.stl"/>
        <mesh class="Armar4" name="HandR_Finger_Index1_joint" file="HandR_Finger_Index1_joint_visu.stl"/>
        <mesh class="Armar4" name="HandR_Finger_Index2_joint" file="HandR_Finger_Index2_joint_visu.stl"/>
        <mesh class="Armar4" name="HandR_Finger_Middle1_joint" file="HandR_Finger_Middle1_joint_visu.stl"/>
        <mesh class="Armar4" name="HandR_Finger_Middle2_joint" file="HandR_Finger_Middle2_joint_visu.stl"/>
        <mesh class="Armar4" name="HandR_Finger_Ring1_joint" file="HandR_Finger_Ring1_joint_visu.stl"/>
        <mesh class="Armar4" name="HandR_Finger_Ring2_joint" file="HandR_Finger_Ring2_joint_visu.stl"/>
        <mesh class="Armar4" name="HandR_Finger_Small1_joint" file="HandR_Finger_Small1_joint_visu.stl"/>
        <mesh class="Armar4" name="HandR_Finger_Small2_joint" file="HandR_Finger_Small2_joint_visu.stl"/>
        <mesh class="Armar4" name="HandR_Finger_Thumb1_joint" file="HandR_Finger_Thumb1_joint_visu.stl"/>
        <mesh class="Armar4" name="HandR_Finger_Thumb2_joint" file="HandR_Finger_Thumb2_joint_visu.stl"/>
        <mesh class="Armar4" name="HandR_Finger_Thumb3_joint" file="HandR_Finger_Thumb3_joint_visu.stl"/>
        <mesh class="Armar4" name="Head_1_joint" file="Head_1_joint_visu.stl"/>
        <mesh class="Armar4" name="Head_2_joint" file="Head_2_joint_visu.stl"/>
        <mesh class="Armar4" name="LegL_Ank2_body" file="LegL_Ank2_joint_visu.stl"/>
        <mesh class="Armar4" name="LegL_Heel_joint" file="LegL_Heel_joint_visu.stl"/>
        <mesh class="Armar4" name="LegL_Hip1_joint" file="LegL_Hip1_joint_visu.stl"/>
        <mesh class="Armar4" name="LegL_Hip2_joint" file="LegL_Hip2_joint_visu.stl"/>
        <mesh class="Armar4" name="LegL_Hip3_joint" file="LegL_Hip3_joint_visu.stl"/>
        <mesh class="Armar4" name="LegL_Knee_joint" file="LegL_Knee_joint_visu.stl"/>
        <mesh class="Armar4" name="LegL_Toe2_joint" file="LegL_Toe2_joint_visu.stl"/>
        <mesh class="Armar4" name="LegL_Toe_joint" file="LegL_Toe_joint_visu.stl"/>
        <mesh class="Armar4" name="LegR_Ank2_body" file="LegR_Ank2_joint_visu.stl"/>
        <mesh class="Armar4" name="LegR_Heel_joint" file="LegR_Heel_joint_visu.stl"/>
        <mesh class="Armar4" name="LegR_Hip1_joint" file="LegR_Hip1_joint_visu.stl"/>
        <mesh class="Armar4" name="LegR_Hip2_joint" file="LegR_Hip2_joint_visu.stl"/>
        <mesh class="Armar4" name="LegR_Hip3_joint" file="LegR_Hip3_joint_visu.stl"/>
        <mesh class="Armar4" name="LegR_Knee_joint" file="LegR_Knee_joint_visu.stl"/>
        <mesh class="Armar4" name="LegR_Toe2_joint" file="LegR_Toe2_joint_visu.stl"/>
        <mesh class="Armar4" name="LegR_Toe_joint" file="LegR_Toe_joint_visu.stl"/>
        <mesh class="Armar4" name="Neck_1_joint" file="Neck_1_joint_visu.stl"/>
        <mesh class="Armar4" name="Neck_2_joint" file="Neck_2_joint_visu.stl"/>
        <mesh class="Armar4" name="Neck_3_joint" file="Neck_3_joint_visu.stl"/>
        <mesh class="Armar4" name="Root_joint" file="Root_joint_visu.stl"/>
        <mesh class="Armar4" name="Torso_Pitch_joint" file="Torso_Pitch_joint_visu.stl"/>
        <mesh class="Armar4" name="Torso_Yaw_joint" file="Torso_Yaw_joint_visu.stl"/>
    </asset>

    <worldbody>
        <body name="Armar4" pos='0 0 1.1' childclass="Armar4">
            <camera name='track' pos='0 -3 1' zaxis='0 -1 0.5' mode='track'/>
            <site name="root" pos="0 0 0" quat="1 0 0 0"/>
            <joint type="free" limited='false' damping="0" stiffness="0" armature="0" name="main"/>
            <body name="Root_joint" pos="0 0 0" quat="1 0 0 0">
                <geom type="mesh" mesh="Root_joint"/>
                <inertial pos="-1.41396e-08 -8.38799e-10 -0.0464755" mass="5" diaginertia="1 1 1"/>
                <body name="Torso_Yaw_joint">
                    <geom type="mesh" mesh="Torso_Yaw_joint"/>
                    <joint name="Torso_Yaw_joint" type="hinge" axis="0 0 1" limited="true" range="-1.5708 1.5708"/>
                    <inertial pos="-0.000749969 -3.16772e-09 0.07458501" mass="5.0100002288818359" diaginertia="0.0137914 0.0165096 0.0117209"/>
                    <body name="Torso_Pitch_joint" pos="0 0 0.099879" quat="0.5 0.5 0.5 0.5">
                        <geom type="mesh" mesh="Torso_Pitch_joint"/>
                        <joint name="Torso_Pitch_joint" type="hinge" axis="0 0 1" limited="true" range="-0.785398 0.785398"/>
                        <inertial pos="-0.0192648 0.13965 -0.000621773" mass="25.489999771118164" diaginertia="0.50297 0.332368 0.479884"/>
                        <body name="ArmL_Sho1_joint" pos="-1.885569e-23 0.2103 -4.547474e-16" quat="0.707107 0.707107 0 6.18173e-08">
                            <geom type="mesh" mesh="ArmL_Sho1_joint"/>
<!--                            <joint name="ArmL_Sho1_joint" type="hinge" axis="0 0 1" limited="true" range="0 0.785398"/>-->
                            <inertial pos="-0.00635488 0.08375741 -0.0328287" mass="0.57999998331069946" diaginertia="0.00137353 0.00204376 0.00196295"/>
                            <body name="ArmL_Sho2_joint" pos="-1.818989e-15 0.136249 -0.05989999" quat="0.793353 0.608762 -8.06879e-09 6.12885e-08">
                                <geom type="mesh" mesh="ArmL_Sho2_joint"/>
<!--                                <joint name="ArmL_Sho2_joint" type="hinge" axis="0 0 1" limited="true" range="-0.523599 2.61799"/>-->
                                <inertial pos="-0.00149987 -0.00344511 -0.0512163" mass="0.51999998092651367" diaginertia="0.000596991 0.000663986 0.000420505"/>
                                <body name="ArmL_Sho3_joint" pos="0.0165 -3.051758e-08 -0.06599998" quat="-0.0308435 0.706434 0.0308436 -0.706434">
                                    <geom type="mesh" mesh="ArmL_Sho3_joint"/>
<!--                                    <joint name="ArmL_Sho3_joint" type="hinge" axis="0 0 1" limited="true" range="-0.261799 1.39626"/>-->
                                    <inertial pos="1.66285e-07 -0.0575318 0.0134998" mass="0.50999999046325684" diaginertia="0.00109943 0.000491725 0.00106067"/>
                                    <body name="ArmL_Sho4_joint" pos="-3.051758e-08 -0.1026 0.0165" quat="0.707107 -0.707107 -1.57009e-15 1.25607e-15">
                                        <geom type="mesh" mesh="ArmL_Sho4_joint"/>
<!--                                        <joint name="ArmL_Sho4_joint" type="hinge" axis="0 0 1" limited="true" range="-1.39626 2.96706"/>-->
                                        <inertial pos="0.00188906 -0.00191048 -0.110437" mass="1.440000057220459" diaginertia="0.00541288 0.00551224 0.0011448"/>
                                        <body name="ArmL_Elb1_joint" pos="-0.02150002 -0.01 -0.1974" quat="0.5 0.5 -0.5 -0.5">
                                            <geom type="mesh" mesh="ArmL_Elb1_joint"/>
<!--                                            <joint name="ArmL_Elb1_joint" type="hinge" axis="0 0 1" limited="true" range="-0.0872665 1.815142"/>-->
                                            <inertial pos="-2.55375e-07 -0.0334756 -0.026321" mass="0.61000001430511475" diaginertia="0.00114668 0.000480917 0.0010953"/>
                                            <body name="ArmL_Elb2_joint" pos="0 -0.08580001 -0.02049998" quat="0.5 -0.5 0.5 0.5">
                                                <geom type="mesh" mesh="ArmL_Elb2_joint"/>
<!--                                                <joint name="ArmL_Elb2_joint" type="hinge" axis="0 0 1" limited="true" range="-3.14159 1.5708"/>-->
                                                <inertial pos="0.00297504 -3.05709e-05 -0.0877993" mass="0.43000000715255737" diaginertia="0.00142316 0.00122507 0.000422436"/>
                                                <body name="ArmL_Wri1_joint" pos="0 0 -0.1642" quat="0.5 -0.5 -0.5 0.5">
                                                    <geom type="mesh" mesh="ArmL_Wri1_joint"/>
<!--                                                    <joint name="ArmL_Wri1_joint" type="hinge" axis="0 0 1" limited="true" range="-0.349066 0.349066"/>-->
                                                    <inertial pos="0 0 -0.0001092625" mass="0.5" diaginertia="3.297112e-05 3.278902e-05 3.315123e-05"/>
                                                    <body name="ArmL_Wri2_joint" quat="0.5 0.5 0.5 0.5">
                                                        <geom type="mesh" mesh="ArmL_Wri2_joint"/>
<!--                                                        <joint name="ArmL_Wri2_joint" type="hinge" axis="0 0 1" limited="true" range="-1.5708 1.5708"/>-->
                                                        <inertial pos="0.0306435 -0.00259348 8.216871e-06" mass="0.57999998331069946" diaginertia="0.000423639 0.0009826689 0.00079084"/>
                                                        <body name="HandL_Finger_Index1_joint" pos="0.08964999 0.009600022 -0.025" quat="0.999048 8.89024e-16 0.0436194 0">
                                                            <geom type="mesh" mesh="HandL_Finger_Index1_joint"/>
<!--                                                            <joint name="HandL_Finger_Index1_joint" type="hinge" axis="0 0 1" limited="true" range="0 1.5708"/>-->
                                                            <inertial pos="0.0221634 -0.008964591 0.00233813" mass="0.05000000074505806" diaginertia="2.07679e-06 1.09969e-05 1.18508e-05"/>
                                                            <body name="HandL_Finger_Index2_joint" pos="0.04529999 -0.0001999969 9.536744e-10">
                                                                <geom type="mesh" mesh="HandL_Finger_Index2_joint"/>
<!--                                                                <joint name="HandL_Finger_Index2_joint" type="hinge" axis="0 0 1" limited="true" range="0 1.5708"/>-->
                                                                <inertial pos="0.0126357 -0.00834728 0.00201315" mass="0.05000000074505806" diaginertia="2.61714e-06 1.64377e-05 1.67053e-05"/>
                                                            </body>
                                                        </body>
                                                        <body name="HandL_Finger_Middle1_joint" pos="0.0913 0.009799988 -0.0047">
                                                            <geom type="mesh" mesh="HandL_Finger_Middle1_joint"/>
<!--                                                            <joint name="HandL_Finger_Middle1_joint" type="hinge" axis="0 0 1" limited="true" range="0 1.5708"/>-->
                                                            <inertial pos="0.0224319 -0.009418661 0.00186457" mass="0.05000000074505806" diaginertia="2.14484e-06 1.08094e-05 1.17542e-05"/>
                                                            <body name="HandL_Finger_Middle2_joint" pos="0.04500003 -0.003049973 9.536744e-10">
                                                                <geom type="mesh" mesh="HandL_Finger_Middle2_joint"/>
<!--                                                                <joint name="HandL_Finger_Middle2_joint" type="hinge" axis="0 0 1" limited="true" range="0 1.5708"/>-->
                                                                <inertial pos="0.0127924 -0.009382 0.00184998" mass="0.05000000074505806" diaginertia="2.71866e-06 1.61015e-05 1.64868e-05"/>
                                                            </body>
                                                        </body>
                                                        <body name="HandL_Finger_Pinky1_joint" pos="0.08845001 0.009700012 0.0317" quat="0.996195 8.91571e-16 -0.0871556 0">
                                                            <geom type="mesh" mesh="HandL_Finger_Pinky1_joint"/>
<!--                                                            <joint name="HandL_Finger_Pinky1_joint" type="hinge" axis="0 0 1" limited="true" range="0 1.5708"/>-->
                                                            <inertial pos="0.0137648 -0.00795003 0.00188619" mass="0.05000000074505806" diaginertia="1.736405e-06 4.737568e-06 5.269918e-06"/>
                                                            <body name="HandL_Finger_Pinky2_joint" pos="0.02700003 -1.525879e-08 0">
                                                                <geom type="mesh" mesh="HandL_Finger_Pinky2_joint"/>
<!--                                                                <joint name="HandL_Finger_Pinky2_joint" type="hinge" axis="0 0 1" limited="true" range="0 1.5708"/>-->
                                                                <inertial pos="0.009930431 -0.00882504 0.00149763" mass="0.05000000074505806" diaginertia="2.14949e-06 1.28698e-05 1.34959e-05"/>
                                                            </body>
                                                        </body>
                                                        <body name="HandL_Finger_Ring1_joint" pos="0.09120002 0.009800019 0.0142" quat="0.999048 2.33053e-10 -0.0436194 0">
                                                            <geom type="mesh" mesh="HandL_Finger_Ring1_joint"/>
<!--                                                            <joint name="HandL_Finger_Ring1_joint" type="hinge" axis="0 0 1" limited="true" range="0 1.5708"/>-->
                                                            <inertial pos="0.0201865 -0.007550021 0.00209084" mass="0.05000000074505806" diaginertia="1.602699e-06 8.853551e-06 9.252926e-06"/>
                                                            <body name="HandL_Finger_Ring2_joint" pos="0.04000003 1.525879e-08 1.907349e-09">
                                                                <geom type="mesh" mesh="HandL_Finger_Ring2_joint"/>
<!--                                                                <joint name="HandL_Finger_Ring2_joint" type="hinge" axis="0 0 1" limited="true" range="0 1.5708"/>-->
                                                                <inertial pos="0.013018 -0.00874729 0.00195051" mass="0.05000000074505806" diaginertia="2.60839e-06 1.61897e-05 1.6466e-05"/>
                                                            </body>
                                                        </body>
                                                        <body name="HandL_Finger_Thumb1_joint" pos="0.0353 0.009800019 -0.0111" quat="0.5 -0.5 0.5 -0.5">
                                                            <geom type="mesh" mesh="HandL_Finger_Thumb1_joint"/>
<!--                                                            <joint name="HandL_Finger_Thumb1_joint" type="hinge" axis="0 0 1" limited="true" range="0 1.5708"/>-->
                                                            <inertial pos="0.009527351 0.0181103 -0.00222519" mass="0.05000000074505806" diaginertia="1.24401e-05 5.68049e-06 9.92836e-06"/>
                                                            <body name="HandL_Finger_Thumb2_joint" pos="0.003499969 0.03 0.004299988" quat="0.707107 7.53644e-15 0.707107 2.51215e-15">
                                                                <geom type="mesh" mesh="HandL_Finger_Thumb2_joint"/>
<!--                                                                <joint name="HandL_Finger_Thumb2_joint" type="hinge" axis="0 0 1" limited="true" range="0 1.5708"/>-->
                                                                <inertial pos="0.009606631 0.0191513 0.00442499" mass="0.05000000074505806" diaginertia="1.06034e-05 3.76921e-06 1.14429e-05"/>
                                                                <body name="HandL_Finger_Thumb3_joint" pos="0.002899994 0.0294 0">
                                                                    <geom type="mesh" mesh="HandL_Finger_Thumb3_joint"/>
<!--                                                                    <joint name="HandL_Finger_Thumb3_joint" type="hinge" axis="0 0 1" limited="true" range="0 1.5708"/>-->
                                                                    <inertial pos="0.000359352 0.0189541 0.00230014" mass="0.05000000074505806" diaginertia="1.05986e-05 3.03593e-06 1.09346e-05"/>
                                                                </body>
                                                            </body>
                                                        </body>
                                                        <site name="HandL_TCP~HandL_GCP" pos="0.06 0.02000002 -9.536744e-10" quat="-0.5 0.5 0.5 0.5"/>
                                                        <site name="HandL_TCP" pos="0.06 0.02000002 -9.536744e-10" quat="-0.5 0.5 0.5 0.5"/>
                                                    </body>
                                                </body>
                                            </body>
                                        </body>
                                    </body>
                                </body>
                            </body>
                        </body>
                        <body name="ArmR_Sho1_joint" pos="-1.885569e-23 0.2103 -4.547474e-16" quat="0.707107 -0.707107 0 0">
                            <geom type="mesh" mesh="ArmR_Sho1_joint"/>
<!--                            <joint name="ArmR_Sho1_joint" type="hinge" axis="0 0 1" limited="true" range="0 0.785398"/>-->
                            <inertial pos="-0.00635496 0.109694 0.0328288" mass="0.76999998092651367" diaginertia="0.00182348 0.00271326 0.00260599"/>
                            <body name="ArmR_Sho2_joint" pos="-4.547483e-16 0.136249 0.05989999" quat="0.793353 -0.608762 -6.12885e-08 8.06879e-09">
                                <geom type="mesh" mesh="ArmR_Sho2_joint"/>
<!--                                <joint name="ArmR_Sho2_joint" type="hinge" axis="0 0 1" limited="true" range="-0.523599 2.61799"/>-->
                                <inertial pos="-0.00150001 -1.73714e-05 0.0492432" mass="0.57999998331069946" diaginertia="0.00061498 0.000689705 0.000469024"/>
                                <body name="ArmR_Sho3_joint" pos="-0.0165 -3.051758e-08 0.06599998" quat="0.706434 -0.0308436 0.706434 -0.0308436">
                                    <geom type="mesh" mesh="ArmR_Sho3_joint"/>
<!--                                    <joint name="ArmR_Sho3_joint" type="hinge" axis="0 0 1" limited="true" range="-0.261799 1.39626"/>-->
                                    <inertial pos="7.45773e-08 0.0575321 0.0195" mass="0.50999999046325684" diaginertia="0.00109943 0.000491725 0.00106067"/>
                                    <body name="ArmR_Sho4_joint" pos="0 0.1026 0.0165" quat="0.707107 -0.707107 3.14018e-15 6.28037e-16">
                                        <geom type="mesh" mesh="ArmR_Sho4_joint"/>
<!--                                        <joint name="ArmR_Sho4_joint" type="hinge" axis="0 0 1" limited="true" range="-1.39626 2.96706"/>-->
                                        <inertial pos="-0.00549999 0.00800005 0.114167" mass="1.440000057220459" diaginertia="0.00678104 0.00688041 0.0011448"/>
                                        <body name="ArmR_Elb1_joint" pos="-0.0215 0.01 0.1974" quat="-0.5 0.5 0.5 -0.5">
                                            <geom type="mesh" mesh="ArmR_Elb1_joint"/>
<!--                                            <joint name="ArmR_Elb1_joint" type="hinge" axis="0 0 1" limited="true" range="-0.0872665 1.815142"/>-->
                                            <inertial pos="-2.35824e-08 -0.0334757 -0.0166789" mass="0.61000001430511475" diaginertia="0.00114668 0.000480918 0.0010953"/>
                                            <body name="ArmR_Elb2_joint" pos="9.536744e-10 -0.08580001 -0.0205" quat="0.5 0.5 0.5 -0.5">
                                                <geom type="mesh" mesh="ArmR_Elb2_joint"/>
<!--                                                <joint name="ArmR_Elb2_joint" type="hinge" axis="0 0 1" limited="true" range="-3.14159 1.5708"/>-->
                                                <inertial pos="-0.0009751351 3.10054e-05 0.08779941" mass="0.43000000715255737" diaginertia="0.00142282 0.00122507 0.000422095"/>
                                                <body name="ArmR_Wri1_joint" pos="-0.0005 9.536744e-10 0.1642" quat="-0.5 -0.5 0.5 0.5">
                                                    <geom type="mesh" mesh="ArmR_Wri1_joint"/>
<!--                                                    <joint name="ArmR_Wri1_joint" type="hinge" axis="0 0 1" limited="true" range="-0.349066 0.349066"/>-->
                                                    <inertial pos="-1.776357e-18 0 -0.0001092625" mass="0.5" diaginertia="3.297112e-05 3.278902e-05 3.315123e-05"/>
                                                    <body name="ArmR_Wri2_joint" pos="9.536744e-10 1.525879e-08 0" quat="-0.5 0.5 0.5 -0.5">
                                                        <geom type="mesh" mesh="ArmR_Wri2_joint"/>
<!--                                                        <joint name="ArmR_Wri2_joint" type="hinge" axis="0 0 1" limited="true" range="-1.5708 1.5708"/>-->
                                                        <inertial pos="0.0306436 -9.36201e-05 -7.883431e-06" mass="0.57999998331069946" diaginertia="0.000423253 0.000982141 0.00079098"/>
                                                        <body name="HandR_Finger_Index1_joint" pos="0.0897 0.01010004 0.023" quat="0.999048 2.33052e-10 -0.0436194 3.72884e-09">
                                                            <geom type="mesh" mesh="HandR_Finger_Index1_joint"/>
<!--                                                            <joint name="HandR_Finger_Index1_joint" type="hinge" axis="0 0 1" limited="true" range="0 1.5708"/>-->
                                                            <inertial pos="0.0226499 -0.00696484 -1.09538e-05" mass="0.05000000074505806" diaginertia="2.07679e-06 1.09969e-05 1.18508e-05"/>
                                                            <body name="HandR_Finger_Index2_joint" pos="0.04524002 0.0001999969 1.907349e-09">
                                                                <geom type="mesh" mesh="HandR_Finger_Index2_joint"/>
<!--                                                                <joint name="HandR_Finger_Index2_joint" type="hinge" axis="0 0 1" limited="true" range="0 1.5708"/>-->
                                                                <inertial pos="0.0129353 -0.00674746 -4.63914e-05" mass="0.05000000074505806" diaginertia="2.61714e-06 1.64377e-05 1.67053e-05"/>
                                                            </body>
                                                        </body>
                                                        <body name="HandR_Finger_Middle1_joint" pos="0.09125008 0.01025002 0.003">
                                                            <geom type="mesh" mesh="HandR_Finger_Middle1_joint"/>
<!--                                                            <joint name="HandR_Finger_Middle1_joint" type="hinge" axis="0 0 1" limited="true" range="0 1.5708"/>-->
                                                            <inertial pos="0.0224819 -0.00736877 -0.00016424" mass="0.05000000074505806" diaginertia="2.02606e-06 1.09037e-05 1.17298e-05"/>
                                                            <body name="HandR_Finger_Middle2_joint" pos="0.045 -0.003 0">
                                                                <geom type="mesh" mesh="HandR_Finger_Middle2_joint"/>
<!--                                                                <joint name="HandR_Finger_Middle2_joint" type="hinge" axis="0 0 1" limited="true" range="0 1.5708"/>-->
                                                                <inertial pos="0.0128425 -0.007382181 -0.000149725" mass="0.05000000074505806" diaginertia="2.7138e-06 1.60995e-05 1.6484e-05"/>
                                                            </body>
                                                        </body>
                                                        <body name="HandR_Finger_Ring1_joint" pos="0.091442 0.01025003 -0.0138" quat="0.999048 -2.33053e-10 0.0436194 3.72884e-09">
                                                            <geom type="mesh" mesh="HandR_Finger_Ring1_joint"/>
<!--                                                            <joint name="HandR_Finger_Ring1_joint" type="hinge" axis="0 0 1" limited="true" range="0 1.5708"/>-->
                                                            <inertial pos="0.0199805 -0.005500081 -0.0025101" mass="0.05000000074505806" diaginertia="1.602894e-06 8.853865e-06 9.253051e-06"/>
                                                            <body name="HandR_Finger_Ring2_joint" pos="0.03999997 0 -1.907349e-09">
                                                                <geom type="mesh" mesh="HandR_Finger_Ring2_joint"/>
<!--                                                                <joint name="HandR_Finger_Ring2_joint" type="hinge" axis="0 0 1" limited="true" range="0 1.5708"/>-->
                                                                <inertial pos="0.0127533 -0.00669734 -0.00250811" mass="0.05000000074505806" diaginertia="2.60839e-06 1.61897e-05 1.64661e-05"/>
                                                            </body>
                                                        </body>
                                                        <body name="HandR_Finger_Small1_joint" pos="0.08883971 0.01024001 -0.0311" quat="0.996195 -4.6744e-10 0.0871556 3.73952e-09">
                                                            <geom type="mesh" mesh="HandR_Finger_Small1_joint"/>
<!--                                                            <joint name="HandR_Finger_Small1_joint" type="hinge" axis="0 0 1" limited="true" range="0 1.5708"/>-->
                                                            <inertial pos="0.0134853 -0.00599024 -0.0025446" mass="0.05000000074505806" diaginertia="1.73657e-06 4.737845e-06 5.270024e-06"/>
                                                            <body name="HandR_Finger_Small2_joint" pos="0.02700006 1.525879e-08 3.814697e-09">
                                                                <geom type="mesh" mesh="HandR_Finger_Small2_joint"/>
<!--                                                                <joint name="HandR_Finger_Small2_joint" type="hinge" axis="0 0 1" limited="true" range="0 1.5708"/>-->
                                                                <inertial pos="0.009687291 -0.00686527 -0.00256493" mass="0.05000000074505806" diaginertia="2.14949e-06 1.28698e-05 1.34958e-05"/>
                                                            </body>
                                                        </body>
                                                        <body name="HandR_Finger_Thumb1_joint" pos="0.03527 0.01025 0.0091" quat="-0.5 -0.5 0.5 0.5">
                                                            <geom type="mesh" mesh="HandR_Finger_Thumb1_joint"/>
<!--                                                            <joint name="HandR_Finger_Thumb1_joint" type="hinge" axis="0 0 1" limited="true" range="0 1.5708"/>-->
                                                            <inertial pos="0.007477561 0.0201107 0.00219502" mass="0.05000000074505806" diaginertia="1.24401e-05 5.68048e-06 9.92836e-06"/>
                                                            <body name="HandR_Finger_Thumb2_joint" pos="0.003749985 0.03 -0.004250015" quat="0.707107 1.29533e-15 -0.707107 -8.83177e-16">
                                                                <geom type="mesh" mesh="HandR_Finger_Thumb2_joint"/>
<!--                                                                <joint name="HandR_Finger_Thumb2_joint" type="hinge" axis="0 0 1" limited="true" range="0 1.5708"/>-->
                                                                <inertial pos="0.0095266 0.0211519 -0.00212523" mass="0.05000000074505806" diaginertia="1.06034e-05 3.76921e-06 1.14429e-05"/>
                                                                <body name="HandR_Finger_Thumb3_joint" pos="0.002899994 0.02938311 0">
                                                                    <geom type="mesh" mesh="HandR_Finger_Thumb3_joint"/>
<!--                                                                    <joint name="HandR_Finger_Thumb3_joint" type="hinge" axis="0 0 1" limited="true" range="0 1.5708"/>-->
                                                                    <inertial pos="0.00180939 0.0220781 -2.20962e-07" mass="0.05000000074505806" diaginertia="1.05987e-05 3.03593e-06 1.09346e-05"/>
                                                                </body>
                                                            </body>
                                                        </body>
                                                        <site name="HandR_TCP~HandR_GCP" pos="0.06000002 0.02000002 0" quat="-0.5 0.5 0.5 0.5"/>
                                                        <site name="HandR_TCP" pos="0.06000002 0.02000002 0" quat="-0.5 0.5 0.5 0.5"/>
                                                    </body>
                                                </body>
                                            </body>
                                        </body>
                                    </body>
                                </body>
                            </body>
                        </body>
                        <site name="TorsoCenter~Chest"/>
                        <body name="Neck_1_joint" pos="-1.567921e-23 0.3073 -4.547474e-16" quat="0.707107 -5.80544e-16 5.56338e-29 -0.707107">
                            <geom type="mesh" mesh="Neck_1_joint"/>
<!--                            <joint name="Neck_1_joint" type="hinge" axis="0 0 1" limited="true" range="-0.785398 0.610865"/>-->
                            <inertial pos="-2.69888e-08 0.0191001 -0.000249887" mass="0.14000000059604645" diaginertia="0.000159421 9.60035e-05 0.000100439"/>
                            <body name="Neck_2_joint" quat="0.5 -0.5 0.5 0.5">
                                <geom type="mesh" mesh="Neck_2_joint"/>
<!--                                <joint name="Neck_2_joint" type="hinge" axis="0 0 1" limited="true" range="-1.22173 1.22173"/>-->
                                <inertial pos="-1.26894e-07 0.0427501 0.0144084" mass="0.12999999523162842" diaginertia="0.000251672 0.000120919 0.000168382"/>
                                <body name="Neck_3_joint" pos="0 0.03379999 0" quat="0.5 -0.5 0.5 0.5">
                                    <geom type="mesh" mesh="Neck_3_joint"/>
<!--                                    <joint name="Neck_3_joint" type="hinge" axis="0 0 1" limited="true" range="-1.5708 1.5708"/>-->
                                    <inertial pos="-0.00675008 -0.0130999 0.0608498" mass="0.25" diaginertia="0.000465112 0.000426562 0.00022281"/>
                                    <body name="Head_1_joint" pos="-1.084202e-22 4.547474e-16 0.1062" quat="-5.33851e-08 -5.33851e-08 0.707107 0.707107">
                                        <geom type="mesh" mesh="Head_1_joint"/>
<!--                                        <joint name="Head_1_joint" type="hinge" axis="0 0 1" limited="true" range="-0.174533 0.610865"/>-->
                                        <inertial pos="0.0100501 5.62238e-08 -0.000349847" mass="0.070000000298023224" diaginertia="2.52845e-05 3.20675e-05 2.7363e-05"/>
                                        <body name="Head_2_joint" pos="0.00465 0 0" quat="0.707107 7.48678e-23 0.707107 0">
                                            <geom type="mesh" mesh="Head_2_joint"/>
<!--                                            <joint name="Head_2_joint" type="hinge" axis="0 0 1" limited="true" range="-0.349066 0.349066"/>-->
                                            <inertial pos="0.00124981 0.0820215 0.0210557" mass="1.3400000333786011" diaginertia="0.00954863 0.00822691 0.00721911"/>
                                            <body name="EyeL_1_joint" pos="-0.0105 0.07265174 -0.06315" quat="-0.5 -0.5 0.5 0.5">
                                                <geom type="mesh" mesh="EyeL_1_joint"/>
<!--                                                <joint name="EyeL_1_joint" type="hinge" axis="0 0 1" limited="true" range="-0.349066 0.349066"/>-->
                                                <body name="EyeL_2_joint" pos="0 0 0.036" quat="-0.5 -0.5 0.5 0.5">
                                                    <geom type="mesh" mesh="EyeL_2_joint"/>
<!--                                                    <joint name="EyeL_2_joint" type="hinge" axis="0 0 1" limited="true" range="-0.698132 0.698132"/>-->
                                                </body>
                                            </body>
                                            <body name="EyeR_1_joint" pos="0.015 0.07265174 -0.06315" quat="-0.5 -0.5 0.5 0.5">
                                                <geom type="mesh" mesh="EyeR_1_joint"/>
<!--                                                <joint name="EyeR_1_joint" type="hinge" axis="0 0 1" limited="true" range="-0.349066 0.349066"/>-->
                                                <body name="EyeR_2_joint" pos="0 0 -0.0315" quat="0.5 -0.5 0.5 -0.5">
                                                    <geom type="mesh" mesh="EyeR_2_joint"/>
<!--                                                    <joint name="EyeR_2_joint" type="hinge" axis="0 0 1" limited="true" range="-0.698132 0.698132"/>-->
                                                </body>
                                            </body>
                                        </body>
                                    </body>
                                </body>
                            </body>
                        </body>
                    </body>
                </body>
                <body name="LegL_Hip1_joint" pos="0.124 0 -0.126" quat="0.953032 0 -0.302869 0">
                    <geom type="mesh" mesh="LegL_Hip1_joint"/>
                    <joint name="LegL_Hip1_joint" type="hinge" axis="0 0 1" limited="true" range="-0.4906 1.5809"/>
                    <inertial pos="-0.0114784 -0.0190205 0.0463836" mass="1.3300000429153442" diaginertia="0.00676843 0.00676843 0.00453669"/>
                    <body name="LegL_Hip2_joint" pos="1.907349e-09 0 0" quat="0.653282 0.270598 -0.653282 0.270598">
                        <geom type="mesh" mesh="LegL_Hip2_joint"/>
                        <joint name="LegL_Hip2_joint" type="hinge" axis="0 0 1" limited="true" range="-0.1853 0.6542"/>
                        <inertial pos="0.000313077 0.0280972 0.00778463" mass="0.36000001430511475" diaginertia="0.000773543 0.000379211 0.000858843"/>
                        <body name="LegL_Hip3_joint" pos="-1.525879e-08 -3.814697e-09 7.629396e-09" quat="0.707107 -0.707107 1.05367e-08 -1.05367e-08">
                            <geom type="mesh" mesh="LegL_Hip3_joint"/>
                            <joint name="LegL_Hip3_joint" type="hinge" axis="0 0 1" limited="true" range="-0.9812 0.8177"/>
                            <inertial pos="-0.149052 -0.134842 0.0788454" mass="5.059999942779541" diaginertia="0.0570551 0.0867303 0.101375"/>
                            <body name="LegL_Knee_joint" pos="-0.3031359 -0.197542 0.173784" quat="0.424681 0.175941 0.820475 0.339868">
                                <geom type="mesh" mesh="LegL_Knee_joint"/>
                                <joint name="LegL_Knee_joint" type="hinge" axis="1 0 0" limited="true" range="0 1.6354"/>
                                <inertial pos="0.0200931 0.0134739 -0.186405" mass="4.25" diaginertia="0.0898909 0.0880982 0.0122883"/>
                                <body name="LegL_Ank1_joint" pos="0 0 -0.4085" quat="0.707107 -1.51557e-12 -0.707107 1.6665e-12">
                                    <joint name="LegL_Ank1_joint" type="hinge" axis="0 0 1" limited="true" range="-0.4906 0.4906"/>
                                    <inertial pos="0 0 -0.0001092625" mass="0.5" diaginertia="3.297112e-05 3.278902e-05 3.315124e-05"/>
                                    <body name="LegL_Ank2_joint" pos="0 0 7.629396e-09" quat="0.707107 0.707107 0 2.57118e-12">
                                        <inertial pos="0 0 0" mass="9.9999997e-05" diaginertia="1 1 1"/>
                                        <joint name="LegL_Ank2_joint" type="hinge" axis="0 0 1" limited="true" range="-0.25 0.25"/>
                                        <body name="LegL_Ank2_body">
                                            <geom type="mesh" mesh="LegL_Ank2_body"/>
                                            <inertial pos="-0.0328382 -0.0160825 0.0358811" mass="1.940000057220459" diaginertia="0.0105498 0.0103366 0.00444324"/>
                                        </body>
                                        <body name="LegL_Heel_joint" pos="-0.0795 0 -0.053" quat="0.707107 -0.707107 -2.5737e-12 -5.0243e-15">
                                            <geom type="mesh" mesh="LegL_Heel_joint"/>
                                            <joint name="LegL_Heel_joint" type="hinge" axis="0 0 1" limited="true" range="0 0.785398"/>
                                        </body>
                                        <site name="LegL_TCP~LegL_TCP2" pos="-0.09 0 0" quat="0.5 0.5 0.5 0.5"/>
                                        <site name="LegL_TCP" pos="-0.09 0 0" quat="0.5 0.5 0.5 0.5"/>
                                        <body name="LegL_Toe2_joint" pos="-0.07419995 -0.0006000061 0.1311" quat="0.843391 -0.5373 -2.15781e-12 2.15676e-12">
                                            <geom type="mesh" mesh="LegL_Toe2_joint"/>
<!--                                            <joint name="LegL_Toe2_joint" type="hinge" axis="0 0 1" limited="true" range="0 0.785398"/>-->
                                        </body>
                                        <body name="LegL_Toe_joint" pos="-0.07423999 0.0244 0.13112" quat="0.707107 -0.707107 -2.5737e-12 -5.0243e-15">
                                            <geom type="mesh" mesh="LegL_Toe_joint"/>
<!--                                            <joint name="LegL_Toe_joint" type="hinge" axis="0 0 1" limited="true" range="0 0.785398"/>-->
                                        </body>
                                    </body>
                                </body>
                            </body>
                        </body>
                    </body>
                </body>
                <body name="LegR_Hip1_joint" pos="-0.124 0 -0.126" quat="-7.19519e-08 0.953032 -2.2866e-08 -0.302869">
                    <geom type="mesh" mesh="LegR_Hip1_joint"/>
                    <joint name="LegR_Hip1_joint" type="hinge" axis="0 0 1" limited="true" range="-0.4906 1.5809"/>
                    <inertial pos="0.00955501 0.0122137 -0.0512045" mass="1.3300000429153442" diaginertia="0.00676843 0.00676844 0.00453669"/>
                    <body name="LegR_Hip2_joint" pos="-1.907349e-09 1.818989e-15 0" quat="0.653282 0.270598 -0.653282 0.270598">
                        <geom type="mesh" mesh="LegR_Hip2_joint"/>
                        <joint name="LegR_Hip2_joint" type="hinge" axis="0 0 1" limited="true" range="-0.1853 0.6541"/>
                        <inertial pos="-0.00120298 -0.0347459 -0.000660893" mass="0.36000001430511475" diaginertia="0.000773544 0.000379211 0.000858844"/>
                        <body name="LegR_Hip3_joint" pos="0 3.814697e-09 -7.629396e-09" quat="0.707107 -0.707107 1.05367e-08 0">
                            <geom type="mesh" mesh="LegR_Hip3_joint"/>
                            <joint name="LegR_Hip3_joint" type="hinge" axis="0 0 1" limited="true" range="-0.9813 0.8177"/>
                            <inertial pos="0.154728 0.131798 -0.06399891" mass="5.059999942779541" diaginertia="0.0570551 0.0867304 0.101375"/>
                            <body name="LegR_Knee_joint" pos="0.3031 0.1975 -0.1738" quat="0.424681 0.175941 0.820475 0.339868">
                                <geom type="mesh" mesh="LegR_Knee_joint"/>
                                <joint name="LegR_Knee_joint" type="hinge" axis="1 0 0" limited="true" range="0 1.6354"/>
                                <inertial pos="-0.0226642 -0.0123348 0.187084" mass="4.25" diaginertia="0.0898961 0.0881157 0.0123005"/>
                                <body name="LegR_Ank1_joint" pos="0 1.907349e-09 0.4085001" quat="0.707107 -1.21897e-12 -0.707107 2.57244e-12">
                                    <joint name="LegR_Ank1_joint" type="hinge" axis="0 0 1" limited="true" range="-0.4906 0.4906"/>
                                    <inertial pos="0 0 -0.0001092625" mass="0.5" diaginertia="3.297112e-05 3.278902e-05 3.315124e-05"/>
                                    <body name="LegR_Ank2_joint" pos="0 0 -7.629396e-09" quat="0.707107 0.707107 1.41063e-17 2.57244e-12">
                                        <inertial pos="0 0 0" mass="9.9999997e-05" diaginertia="1 1 1"/>
                                        <joint name="LegR_Ank2_joint" type="hinge" axis="0 0 1" limited="true" range="-0.25 0.25"/>
                                        <body name="LegR_Ank2_body">
                                            <geom type="mesh" mesh="LegR_Ank2_body"/>
                                            <inertial pos="0.0333756 0.0137197 -0.0381945" mass="1.940000057220459" diaginertia="0.0105497 0.0103369 0.00444379"/>
                                        </body>
                                        <body name="LegR_Heel_joint" pos="0.07944995 0 0.05290001">
                                            <geom type="mesh" mesh="LegR_Heel_joint"/>
                                            <joint name="LegR_Heel_joint" type="hinge" axis="0 1 0" limited="true" range="0 0.785398"/>
                                        </body>
                                        <site name="LegR_TCP~LegR_TCP2" pos="0.09 0 1.907349e-09" quat="0.5 -0.5 -0.5 0.5"/>
                                        <site name="LegR_TCP" pos="0.09 0 1.907349e-09" quat="0.5 -0.5 -0.5 0.5"/>
                                        <body name="LegR_Toe2_joint" pos="0.07429999 0.0005999908 -0.1312" quat="0.843391 -0.5373 -2.16097e-12 1.07838e-12">
                                            <geom type="mesh" mesh="LegR_Toe2_joint"/>
<!--                                            <joint name="LegR_Toe2_joint" type="hinge" axis="0 0 1" limited="true" range="0 0.785398"/>-->
                                        </body>
                                        <body name="LegR_Toe_joint" pos="0.07429999 -0.02540001 -0.13117" quat="-7.5498e-08 -1.81899e-12 1 2.57528e-13">
                                            <geom type="mesh" mesh="LegR_Toe_joint"/>
<!--                                            <joint name="LegR_Toe_joint" type="hinge" axis="0 1 0" limited="true" range="0 0.785398"/>-->
                                        </body>
                                    </body>
                                </body>
                            </body>
                        </body>
                    </body>
                </body>
                <site name="Pelvis"/>
            </body>
        </body>
    </worldbody>
    <contact>
        <exclude body1="Armar4" body2="Root_joint"/>
        <exclude body1="Root_joint" body2="Torso_Yaw_joint"/>
        <exclude body1="Torso_Yaw_joint" body2="Torso_Pitch_joint"/>
        <exclude body1="Torso_Pitch_joint" body2="ArmL_Sho1_joint"/>
        <exclude body1="ArmL_Sho1_joint" body2="ArmL_Sho2_joint"/>
        <exclude body1="ArmL_Sho2_joint" body2="ArmL_Sho3_joint"/>
        <exclude body1="ArmL_Sho3_joint" body2="ArmL_Sho4_joint"/>
        <exclude body1="ArmL_Sho4_joint" body2="ArmL_Elb1_joint"/>
        <exclude body1="ArmL_Elb1_joint" body2="ArmL_Elb2_joint"/>
        <exclude body1="ArmL_Elb2_joint" body2="ArmL_Wri1_joint"/>
        <exclude body1="ArmL_Wri1_joint" body2="ArmL_Wri2_joint"/>
        <exclude body1="ArmL_Wri2_joint" body2="HandL_Finger_Index1_joint"/>
        <exclude body1="HandL_Finger_Index1_joint" body2="HandL_Finger_Index2_joint"/>
        <exclude body1="ArmL_Wri2_joint" body2="HandL_Finger_Middle1_joint"/>
        <exclude body1="HandL_Finger_Middle1_joint" body2="HandL_Finger_Middle2_joint"/>
        <exclude body1="ArmL_Wri2_joint" body2="HandL_Finger_Pinky1_joint"/>
        <exclude body1="HandL_Finger_Pinky1_joint" body2="HandL_Finger_Pinky2_joint"/>
        <exclude body1="ArmL_Wri2_joint" body2="HandL_Finger_Ring1_joint"/>
        <exclude body1="HandL_Finger_Ring1_joint" body2="HandL_Finger_Ring2_joint"/>
        <exclude body1="ArmL_Wri2_joint" body2="HandL_Finger_Thumb1_joint"/>
        <exclude body1="HandL_Finger_Thumb1_joint" body2="HandL_Finger_Thumb2_joint"/>
        <exclude body1="HandL_Finger_Thumb2_joint" body2="HandL_Finger_Thumb3_joint"/>
        <exclude body1="Torso_Pitch_joint" body2="ArmR_Sho1_joint"/>
        <exclude body1="ArmR_Sho1_joint" body2="ArmR_Sho2_joint"/>
        <exclude body1="ArmR_Sho2_joint" body2="ArmR_Sho3_joint"/>
        <exclude body1="ArmR_Sho3_joint" body2="ArmR_Sho4_joint"/>
        <exclude body1="ArmR_Sho4_joint" body2="ArmR_Elb1_joint"/>
        <exclude body1="ArmR_Elb1_joint" body2="ArmR_Elb2_joint"/>
        <exclude body1="ArmR_Elb2_joint" body2="ArmR_Wri1_joint"/>
        <exclude body1="ArmR_Wri1_joint" body2="ArmR_Wri2_joint"/>
        <exclude body1="ArmR_Wri2_joint" body2="HandR_Finger_Index1_joint"/>
        <exclude body1="HandR_Finger_Index1_joint" body2="HandR_Finger_Index2_joint"/>
        <exclude body1="ArmR_Wri2_joint" body2="HandR_Finger_Middle1_joint"/>
        <exclude body1="HandR_Finger_Middle1_joint" body2="HandR_Finger_Middle2_joint"/>
        <exclude body1="ArmR_Wri2_joint" body2="HandR_Finger_Ring1_joint"/>
        <exclude body1="HandR_Finger_Ring1_joint" body2="HandR_Finger_Ring2_joint"/>
        <exclude body1="ArmR_Wri2_joint" body2="HandR_Finger_Small1_joint"/>
        <exclude body1="HandR_Finger_Small1_joint" body2="HandR_Finger_Small2_joint"/>
        <exclude body1="ArmR_Wri2_joint" body2="HandR_Finger_Thumb1_joint"/>
        <exclude body1="HandR_Finger_Thumb1_joint" body2="HandR_Finger_Thumb2_joint"/>
        <exclude body1="HandR_Finger_Thumb2_joint" body2="HandR_Finger_Thumb3_joint"/>
        <exclude body1="Torso_Pitch_joint" body2="Neck_1_joint"/>
        <exclude body1="Neck_1_joint" body2="Neck_2_joint"/>
        <exclude body1="Neck_2_joint" body2="Neck_3_joint"/>
        <exclude body1="Neck_3_joint" body2="Head_1_joint"/>
        <exclude body1="Head_1_joint" body2="Head_2_joint"/>
        <exclude body1="Head_2_joint" body2="EyeL_1_joint"/>
        <exclude body1="EyeL_1_joint" body2="EyeL_2_joint"/>
        <exclude body1="Head_2_joint" body2="EyeR_1_joint"/>
        <exclude body1="EyeR_1_joint" body2="EyeR_2_joint"/>
        <exclude body1="Root_joint" body2="LegL_Hip1_joint"/>
        <exclude body1="LegL_Hip1_joint" body2="LegL_Hip2_joint"/>
        <exclude body1="LegL_Hip2_joint" body2="LegL_Hip3_joint"/>
        <exclude body1="LegL_Hip3_joint" body2="LegL_Knee_joint"/>
        <exclude body1="LegL_Knee_joint" body2="LegL_Ank1_joint"/>
        <exclude body1="LegL_Ank1_joint" body2="LegL_Ank2_joint"/>
        <exclude body1="LegL_Ank2_joint" body2="LegL_Ank2_body"/>
        <exclude body1="LegL_Ank2_joint" body2="LegL_Heel_joint"/>
        <exclude body1="LegL_Ank2_joint" body2="LegL_Toe2_joint"/>
        <exclude body1="LegL_Ank2_joint" body2="LegL_Toe_joint"/>
        <exclude body1="Root_joint" body2="LegR_Hip1_joint"/>
        <exclude body1="LegR_Hip1_joint" body2="LegR_Hip2_joint"/>
        <exclude body1="LegR_Hip2_joint" body2="LegR_Hip3_joint"/>
        <exclude body1="LegR_Hip3_joint" body2="LegR_Knee_joint"/>
        <exclude body1="LegR_Knee_joint" body2="LegR_Ank1_joint"/>
        <exclude body1="LegR_Ank1_joint" body2="LegR_Ank2_joint"/>
        <exclude body1="LegR_Ank2_joint" body2="LegR_Ank2_body"/>
        <exclude body1="LegR_Ank2_joint" body2="LegR_Heel_joint"/>
        <exclude body1="LegR_Ank2_joint" body2="LegR_Toe2_joint"/>
        <exclude body1="LegR_Ank2_joint" body2="LegR_Toe_joint"/>
    </contact>

    <actuator>
        <motor class="Armar4" name="Torso_Yaw_joint" joint="Torso_Yaw_joint" ctrlrange="-50 50"/>
        <motor class="Armar4" name="Torso_Pitch_joint" joint="Torso_Pitch_joint" ctrlrange="-50 50"/>
<!--        <motor class="Armar4" name="ArmL_Sho1_joint" joint="ArmL_Sho1_joint" ctrlrange="-30 30"/>-->
<!--        <motor class="Armar4" name="ArmL_Sho2_joint" joint="ArmL_Sho2_joint" ctrlrange="-30 30"/>-->
<!--        <motor class="Armar4" name="ArmL_Sho3_joint" joint="ArmL_Sho3_joint" ctrlrange="-30 30"/>-->
<!--        <motor class="Armar4" name="ArmL_Sho4_joint" joint="ArmL_Sho4_joint" ctrlrange="-30 30"/>-->
<!--        <motor class="Armar4" name="ArmL_Elb1_joint" joint="ArmL_Elb1_joint" ctrlrange="-20 20"/>-->
<!--        <motor class="Armar4" name="ArmL_Elb2_joint" joint="ArmL_Elb2_joint" ctrlrange="-20 20"/>-->
<!--        <motor class="Armar4" name="ArmL_Wri1_joint" joint="ArmL_Wri1_joint" ctrlrange="-20 20"/>-->
<!--        <motor class="Armar4" name="ArmL_Wri2_joint" joint="ArmL_Wri2_joint" ctrlrange="-20 20"/>-->
<!--        <motor class="Armar4" name="HandL_Finger_Index1_joint" joint="HandL_Finger_Index1_joint"/>-->
<!--        <motor class="Armar4" name="HandL_Finger_Index2_joint" joint="HandL_Finger_Index2_joint"/>-->
<!--        <motor class="Armar4" name="HandL_Finger_Middle1_joint" joint="HandL_Finger_Middle1_joint"/>-->
<!--        <motor class="Armar4" name="HandL_Finger_Middle2_joint" joint="HandL_Finger_Middle2_joint"/>-->
<!--        <motor class="Armar4" name="HandL_Finger_Pinky1_joint" joint="HandL_Finger_Pinky1_joint"/>-->
<!--        <motor class="Armar4" name="HandL_Finger_Pinky2_joint" joint="HandL_Finger_Pinky2_joint"/>-->
<!--        <motor class="Armar4" name="HandL_Finger_Ring1_joint" joint="HandL_Finger_Ring1_joint"/>-->
<!--        <motor class="Armar4" name="HandL_Finger_Ring2_joint" joint="HandL_Finger_Ring2_joint"/>-->
<!--        <motor class="Armar4" name="HandL_Finger_Thumb1_joint" joint="HandL_Finger_Thumb1_joint"/>-->
<!--        <motor class="Armar4" name="HandL_Finger_Thumb2_joint" joint="HandL_Finger_Thumb2_joint"/>-->
<!--        <motor class="Armar4" name="HandL_Finger_Thumb3_joint" joint="HandL_Finger_Thumb3_joint"/>-->
<!--        <motor class="Armar4" name="ArmR_Sho1_joint" joint="ArmR_Sho1_joint" ctrlrange="-30 30"/>-->
<!--        <motor class="Armar4" name="ArmR_Sho2_joint" joint="ArmR_Sho2_joint" ctrlrange="-30 30"/>-->
<!--        <motor class="Armar4" name="ArmR_Sho3_joint" joint="ArmR_Sho3_joint" ctrlrange="-30 30"/>-->
<!--        <motor class="Armar4" name="ArmR_Sho4_joint" joint="ArmR_Sho4_joint" ctrlrange="-30 30"/>-->
<!--        <motor class="Armar4" name="ArmR_Elb1_joint" joint="ArmR_Elb1_joint" ctrlrange="-20 20"/>-->
<!--        <motor class="Armar4" name="ArmR_Elb2_joint" joint="ArmR_Elb2_joint" ctrlrange="-20 20"/>-->
<!--        <motor class="Armar4" name="ArmR_Wri1_joint" joint="ArmR_Wri1_joint" ctrlrange="-20 20"/>-->
<!--        <motor class="Armar4" name="ArmR_Wri2_joint" joint="ArmR_Wri2_joint" ctrlrange="-20 20"/>-->
<!--        <motor class="Armar4" name="HandR_Finger_Index1_joint" joint="HandR_Finger_Index1_joint"/>-->
<!--        <motor class="Armar4" name="HandR_Finger_Index2_joint" joint="HandR_Finger_Index2_joint"/>-->
<!--        <motor class="Armar4" name="HandR_Finger_Middle1_joint" joint="HandR_Finger_Middle1_joint"/>-->
<!--        <motor class="Armar4" name="HandR_Finger_Middle2_joint" joint="HandR_Finger_Middle2_joint"/>-->
<!--        <motor class="Armar4" name="HandR_Finger_Ring1_joint" joint="HandR_Finger_Ring1_joint"/>-->
<!--        <motor class="Armar4" name="HandR_Finger_Ring2_joint" joint="HandR_Finger_Ring2_joint"/>-->
<!--        <motor class="Armar4" name="HandR_Finger_Small1_joint" joint="HandR_Finger_Small1_joint"/>-->
<!--        <motor class="Armar4" name="HandR_Finger_Small2_joint" joint="HandR_Finger_Small2_joint"/>-->
<!--        <motor class="Armar4" name="HandR_Finger_Thumb1_joint" joint="HandR_Finger_Thumb1_joint"/>-->
<!--        <motor class="Armar4" name="HandR_Finger_Thumb2_joint" joint="HandR_Finger_Thumb2_joint"/>-->
<!--        <motor class="Armar4" name="HandR_Finger_Thumb3_joint" joint="HandR_Finger_Thumb3_joint"/>-->
<!--        <motor class="Armar4" name="Neck_1_joint" joint="Neck_1_joint" ctrlrange="-20 20"/>-->
<!--        <motor class="Armar4" name="Neck_2_joint" joint="Neck_2_joint" ctrlrange="-20 20"/>-->
<!--        <motor class="Armar4" name="Neck_3_joint" joint="Neck_3_joint" ctrlrange="-20 20"/>-->
<!--        <motor class="Armar4" name="Head_1_joint" joint="Head_1_joint"/>-->
<!--        <motor class="Armar4" name="Head_2_joint" joint="Head_2_joint"/>-->
<!--        <motor class="Armar4" name="EyeL_1_joint" joint="EyeL_1_joint"/>-->
<!--        <motor class="Armar4" name="EyeL_2_joint" joint="EyeL_2_joint"/>-->
<!--        <motor class="Armar4" name="EyeR_1_joint" joint="EyeR_1_joint"/>-->
<!--        <motor class="Armar4" name="EyeR_2_joint" joint="EyeR_2_joint"/>-->
        <motor class="Armar4" name="LegL_Hip1_joint" joint="LegL_Hip1_joint" ctrlrange="-50 50"/>
        <motor class="Armar4" name="LegL_Hip2_joint" joint="LegL_Hip2_joint" ctrlrange="-50 60"/>
        <motor class="Armar4" name="LegL_Hip3_joint" joint="LegL_Hip3_joint" ctrlrange="-50 50"/>
        <motor class="Armar4" name="LegL_Knee_joint" joint="LegL_Knee_joint" ctrlrange="-50 50"/>
        <motor class="Armar4" name="LegL_Ank1_joint" joint="LegL_Ank1_joint" ctrlrange="-30 30"/>
        <motor class="Armar4" name="LegL_Ank2_joint" joint="LegL_Ank2_joint" ctrlrange="-30 30"/>
        <motor class="Armar4" name="LegL_Heel_joint" joint="LegL_Heel_joint" ctrlrange="-30 30"/>
<!--        <motor class="Armar4" name="LegL_Toe2_joint" joint="LegL_Toe2_joint" ctrlrange="-1 1"/>-->
<!--        <motor class="Armar4" name="LegL_Toe_joint" joint="LegL_Toe_joint" ctrlrange="-1 1"/>-->
        <motor class="Armar4" name="LegR_Hip1_joint" joint="LegR_Hip1_joint" ctrlrange="-50 50"/>
        <motor class="Armar4" name="LegR_Hip2_joint" joint="LegR_Hip2_joint" ctrlrange="-50 50"/>
        <motor class="Armar4" name="LegR_Hip3_joint" joint="LegR_Hip3_joint" ctrlrange="-50 50"/>
        <motor class="Armar4" name="LegR_Knee_joint" joint="LegR_Knee_joint" ctrlrange="-50 50"/>
        <motor class="Armar4" name="LegR_Ank1_joint" joint="LegR_Ank1_joint" ctrlrange="-30 30"/>
        <motor class="Armar4" name="LegR_Ank2_joint" joint="LegR_Ank2_joint" ctrlrange="-30 30"/>
        <motor class="Armar4" name="LegR_Heel_joint" joint="LegR_Heel_joint" ctrlrange="-30 30"/>
<!--        <motor class="Armar4" name="LegR_Toe2_joint" joint="LegR_Toe2_joint" ctrlrange="-50 50"/>-->
<!--        <motor class="Armar4" name="LegR_Toe_joint" joint="LegR_Toe_joint" ctrlrange="-50 50"/>-->
    </actuator>
</mujocoinclude>
